[04/Aug/2018 19:44:51] "GET /admin/ HTTP/1.1" 200 2739
[04/Aug/2018 19:44:52] "GET /admin/ HTTP/1.1" 200 2739
[04/Aug/2018 19:44:52] "GET /admin/ HTTP/1.1" 200 2739
[04/Aug/2018 19:44:53] "GET /admin/ HTTP/1.1" 200 2739
[04/Aug/2018 19:44:54] "GET /admin/auth/group/ HTTP/1.1" 200 3358
[04/Aug/2018 19:44:54] "GET /admin/jsi18n/ HTTP/1.1" 200 7682
[04/Aug/2018 19:44:55] "GET /admin/ HTTP/1.1" 200 2739
[04/Aug/2018 19:45:28] "GET / HTTP/1.1" 200 1714
[04/Aug/2018 19:45:31] "GET /admin/ HTTP/1.1" 200 2739
[04/Aug/2018 19:45:32] "GET /admin/password_change/ HTTP/1.1" 200 2518
[04/Aug/2018 19:45:32] "GET /static/admin/css/forms.css HTTP/1.1" 200 8173
[04/Aug/2018 19:45:32] "GET /static/admin/css/widgets.css HTTP/1.1" 200 10340
[04/Aug/2018 19:45:35] "GET /admin/ HTTP/1.1" 200 2739
[04/Aug/2018 19:45:36] "GET /admin/logout/ HTTP/1.1" 200 1011
[04/Aug/2018 19:45:39] "GET /admin/ HTTP/1.1" 302 0
[04/Aug/2018 19:45:39] "GET /admin/login/?next=/admin/ HTTP/1.1" 200 1652
[04/Aug/2018 19:45:39] "GET /static/admin/css/login.css HTTP/1.1" 304 0
[04/Aug/2018 19:45:40] "POST /admin/login/?next=/admin/ HTTP/1.1" 302 0
[04/Aug/2018 19:45:40] "GET /admin/ HTTP/1.1" 200 2739
[04/Aug/2018 19:45:43] "GET /admin/auth/user/ HTTP/1.1" 200 6484
[04/Aug/2018 19:45:43] "GET /admin/jsi18n/ HTTP/1.1" 200 7682
[04/Aug/2018 19:45:44] "GET /admin/ HTTP/1.1" 200 2739
[04/Aug/2018 19:45:45] "GET /admin/auth/group/ HTTP/1.1" 200 3358
[04/Aug/2018 19:45:45] "GET /admin/jsi18n/ HTTP/1.1" 200 7682
[04/Aug/2018 19:45:47] "GET /admin/ HTTP/1.1" 200 2739
Not Found: /static
[04/Aug/2018 19:50:01] "GET /static HTTP/1.1" 404 1947
[04/Aug/2018 19:50:15] "GET /static/ HTTP/1.1" 404 1611
Performing system checks...

System check identified no issues (0 silenced).
August 04, 2018 - 19:44:48
Django version 1.11.6, using settings 'mysite.settings'
Starting development server at http://127.0.0.1:8000/
Quit the server with CONTROL-C.
[04/Aug/2018 20:01:42] "GET / HTTP/1.1" 200 1714
Performing system checks...

System check identified no issues (0 silenced).
August 04, 2018 - 20:01:37
Django version 1.11.6, using settings 'mysite.settings'
Starting development server at http://127.0.0.1:8000/
Quit the server with CONTROL-C.
[04/Aug/2018 20:18:12] "GET / HTTP/1.1" 200 1714
[04/Aug/2018 20:18:14] "GET / HTTP/1.1" 200 1714
Performing system checks...

System check identified no issues (0 silenced).
August 04, 2018 - 20:16:52
Django version 1.11.6, using settings 'mysite.settings'
Starting development server at http://127.0.0.1:8000/
Quit the server with CONTROL-C.
Performing system checks...

System check identified no issues (0 silenced).
August 04, 2018 - 20:27:36
Django version 1.11.6, using settings 'mysite.settings'
Starting development server at http://127.0.0.1:8000/
Quit the server with CONTROL-C.
Unhandled exception in thread started by <function check_errors.<locals>.wrapper at 0x7fee69479730>
Traceback (most recent call last):
  File "/home/django_web/pyproject/django_en/lib/python3.6/site-packages/django/utils/autoreload.py", line 228, in wrapper
    fn(*args, **kwargs)
  File "/home/django_web/pyproject/django_en/lib/python3.6/site-packages/django/core/management/commands/runserver.py", line 125, in inner_run
    self.check(display_num_errors=True)
  File "/home/django_web/pyproject/django_en/lib/python3.6/site-packages/django/core/management/base.py", line 359, in check
    include_deployment_checks=include_deployment_checks,
  File "/home/django_web/pyproject/django_en/lib/python3.6/site-packages/django/core/management/base.py", line 346, in _run_checks
    return checks.run_checks(**kwargs)
  File "/home/django_web/pyproject/django_en/lib/python3.6/site-packages/django/core/checks/registry.py", line 81, in run_checks
    new_errors = check(app_configs=app_configs)
  File "/home/django_web/pyproject/django_en/lib/python3.6/site-packages/django/core/checks/urls.py", line 16, in check_url_config
    return check_resolver(resolver)
  File "/home/django_web/pyproject/django_en/lib/python3.6/site-packages/django/core/checks/urls.py", line 26, in check_resolver
    return check_method()
  File "/home/django_web/pyproject/django_en/lib/python3.6/site-packages/django/urls/resolvers.py", line 254, in check
    for pattern in self.url_patterns:
  File "/home/django_web/pyproject/django_en/lib/python3.6/site-packages/django/utils/functional.py", line 35, in __get__
    res = instance.__dict__[self.name] = self.func(instance)
  File "/home/django_web/pyproject/django_en/lib/python3.6/site-packages/django/urls/resolvers.py", line 405, in url_patterns
    patterns = getattr(self.urlconf_module, "urlpatterns", self.urlconf_module)
  File "/home/django_web/pyproject/django_en/lib/python3.6/site-packages/django/utils/functional.py", line 35, in __get__
    res = instance.__dict__[self.name] = self.func(instance)
  File "/home/django_web/pyproject/django_en/lib/python3.6/site-packages/django/urls/resolvers.py", line 398, in urlconf_module
    return import_module(self.urlconf_name)
  File "/usr/local/lib/python3.6/importlib/__init__.py", line 126, in import_module
    return _bootstrap._gcd_import(name[level:], package, level)
  File "<frozen importlib._bootstrap>", line 978, in _gcd_import
  File "<frozen importlib._bootstrap>", line 961, in _find_and_load
  File "<frozen importlib._bootstrap>", line 950, in _find_and_load_unlocked
  File "<frozen importlib._bootstrap>", line 655, in _load_unlocked
  File "<frozen importlib._bootstrap_external>", line 678, in exec_module
  File "<frozen importlib._bootstrap>", line 205, in _call_with_frames_removed
  File "/home/django_web/pyproject/mysite/mysite/urls.py", line 22, in <module>
    url(r'^polls/', include('polls.urls'))
  File "/home/django_web/pyproject/django_en/lib/python3.6/site-packages/django/conf/urls/__init__.py", line 50, in include
    urlconf_module = import_module(urlconf_module)
  File "/usr/local/lib/python3.6/importlib/__init__.py", line 126, in import_module
    return _bootstrap._gcd_import(name[level:], package, level)
  File "<frozen importlib._bootstrap>", line 978, in _gcd_import
  File "<frozen importlib._bootstrap>", line 961, in _find_and_load
  File "<frozen importlib._bootstrap>", line 950, in _find_and_load_unlocked
  File "<frozen importlib._bootstrap>", line 655, in _load_unlocked
  File "<frozen importlib._bootstrap_external>", line 678, in exec_module
  File "<frozen importlib._bootstrap>", line 205, in _call_with_frames_removed
  File "/home/django_web/pyproject/mysite/polls/urls.py", line 4, in <module>
    url(r'^$',view=views.index,name="index")
AttributeError: module 'polls.views' has no attribute 'index'
Performing system checks...

Performing system checks...

System check identified no issues (0 silenced).
August 04, 2018 - 20:39:52
Django version 1.11.6, using settings 'mysite.settings'
Starting development server at http://127.0.0.1:8000/
Quit the server with CONTROL-C.
Not Found: /
[04/Aug/2018 20:42:11] "GET / HTTP/1.1" 404 2018
Not Found: /
[04/Aug/2018 20:42:12] "GET / HTTP/1.1" 404 2018
Not Found: /
[04/Aug/2018 20:42:13] "GET / HTTP/1.1" 404 2018
[04/Aug/2018 20:42:19] "GET /polls HTTP/1.1" 301 0
[04/Aug/2018 20:42:19] "GET /polls/ HTTP/1.1" 200 147
[05/Aug/2018 09:08:23] "GET /polls/ HTTP/1.1" 200 147
Not Found: /favicon.ico
[05/Aug/2018 09:08:23] "GET /favicon.ico HTTP/1.1" 404 2069
Not Found: /
[05/Aug/2018 10:04:52] "GET / HTTP/1.1" 404 2018
Not Found: /
[05/Aug/2018 10:04:54] "GET / HTTP/1.1" 404 2018
Not Found: /
[05/Aug/2018 10:04:55] "GET / HTTP/1.1" 404 2018
Not Found: /
[05/Aug/2018 10:04:59] "GET / HTTP/1.1" 404 2018
[05/Aug/2018 10:05:25] "GET /admin/ HTTP/1.1" 200 2739
[05/Aug/2018 10:05:25] "GET /static/admin/css/dashboard.css HTTP/1.1" 200 412
[05/Aug/2018 10:05:25] "GET /static/admin/css/base.css HTTP/1.1" 200 16066
[05/Aug/2018 10:05:25] "GET /static/admin/css/fonts.css HTTP/1.1" 200 423
[05/Aug/2018 10:05:25] "GET /static/admin/img/icon-addlink.svg HTTP/1.1" 200 331
[05/Aug/2018 10:05:25] "GET /static/admin/fonts/Roboto-Light-webfont.woff HTTP/1.1" 200 81348
[05/Aug/2018 10:05:25] "GET /static/admin/fonts/Roboto-Bold-webfont.woff HTTP/1.1" 200 82564
[05/Aug/2018 10:05:25] "GET /static/admin/fonts/Roboto-Regular-webfont.woff HTTP/1.1" 200 80304
[05/Aug/2018 10:05:25] "GET /static/admin/img/icon-changelink.svg HTTP/1.1" 200 380
[05/Aug/2018 10:05:28] "GET /admin/auth/group/ HTTP/1.1" 200 3358
[05/Aug/2018 10:05:28] "GET /static/admin/css/changelists.css HTTP/1.1" 200 6170
[05/Aug/2018 10:05:28] "GET /static/admin/js/urlify.js HTTP/1.1" 200 8186
[05/Aug/2018 10:05:28] "GET /static/admin/js/core.js HTTP/1.1" 200 7976
[05/Aug/2018 10:05:28] "GET /static/admin/js/vendor/jquery/jquery.js HTTP/1.1" 200 258648
[05/Aug/2018 10:05:28] "GET /static/admin/js/vendor/xregexp/xregexp.js HTTP/1.1" 200 128820
[05/Aug/2018 10:05:28] "GET /static/admin/js/jquery.init.js HTTP/1.1" 200 363
[05/Aug/2018 10:05:28] "GET /static/admin/js/prepopulate.js HTTP/1.1" 200 1538
[05/Aug/2018 10:05:28] "GET /static/admin/js/admin/RelatedObjectLookups.js HTTP/1.1" 200 6591
[05/Aug/2018 10:05:28] "GET /static/admin/js/actions.js HTTP/1.1" 200 6501
[05/Aug/2018 10:05:28] "GET /admin/jsi18n/ HTTP/1.1" 200 7682
[05/Aug/2018 10:05:28] "GET /static/admin/img/search.svg HTTP/1.1" 200 458
[05/Aug/2018 10:05:28] "GET /static/admin/img/tooltag-add.svg HTTP/1.1" 200 331
[05/Aug/2018 10:05:29] "GET /admin/ HTTP/1.1" 200 2739
[05/Aug/2018 10:05:30] "GET /admin/auth/user/ HTTP/1.1" 200 6484
[05/Aug/2018 10:05:30] "GET /admin/jsi18n/ HTTP/1.1" 200 7682
[05/Aug/2018 10:05:30] "GET /static/admin/img/icon-yes.svg HTTP/1.1" 200 436
[05/Aug/2018 10:05:30] "GET /static/admin/img/sorting-icons.svg HTTP/1.1" 200 1097
[05/Aug/2018 10:05:33] "GET /admin/ HTTP/1.1" 200 2739
Not Found: /
[05/Aug/2018 10:25:29] "GET / HTTP/1.1" 404 2018
Not Found: /favicon.ico
[05/Aug/2018 10:25:29] "GET /favicon.ico HTTP/1.1" 404 2069
[05/Aug/2018 10:41:20] "GET /polls/ HTTP/1.1" 200 147
Performing system checks...

System check identified no issues (0 silenced).
August 05, 2018 - 09:08:00
Django version 1.11.6, using settings 'mysite.settings'
Starting development server at http://127.0.0.1:8000/
Quit the server with CONTROL-C.
Performing system checks...

System check identified no issues (0 silenced).
August 05, 2018 - 10:52:45
Django version 1.11.6, using settings 'mysite.settings'
Starting development server at http://127.0.0.1:8000/
Quit the server with CONTROL-C.
Performing system checks...

System check identified no issues (0 silenced).
August 05, 2018 - 10:53:16
Django version 1.11.6, using settings 'mysite.settings'
Starting development server at http://127.0.0.1:8000/
Quit the server with CONTROL-C.
Unhandled exception in thread started by <function check_errors.<locals>.wrapper at 0x7fa0aa678f28>
Traceback (most recent call last):
  File "/usr/local/lib/python3.6/site-packages/django/utils/autoreload.py", line 228, in wrapper
    fn(*args, **kwargs)
  File "/usr/local/lib/python3.6/site-packages/django/core/management/commands/runserver.py", line 117, in inner_run
    autoreload.raise_last_exception()
  File "/usr/local/lib/python3.6/site-packages/django/utils/autoreload.py", line 251, in raise_last_exception
    six.reraise(*_exception)
  File "/usr/local/lib/python3.6/site-packages/django/utils/six.py", line 685, in reraise
    raise value.with_traceback(tb)
  File "/usr/local/lib/python3.6/site-packages/django/utils/autoreload.py", line 228, in wrapper
    fn(*args, **kwargs)
  File "/usr/local/lib/python3.6/site-packages/django/__init__.py", line 27, in setup
    apps.populate(settings.INSTALLED_APPS)
  File "/usr/local/lib/python3.6/site-packages/django/apps/registry.py", line 108, in populate
    app_config.import_models()
  File "/usr/local/lib/python3.6/site-packages/django/apps/config.py", line 202, in import_models
    self.models_module = import_module(models_module_name)
  File "/usr/local/lib/python3.6/importlib/__init__.py", line 126, in import_module
    return _bootstrap._gcd_import(name[level:], package, level)
  File "<frozen importlib._bootstrap>", line 978, in _gcd_import
  File "<frozen importlib._bootstrap>", line 961, in _find_and_load
  File "<frozen importlib._bootstrap>", line 950, in _find_and_load_unlocked
  File "<frozen importlib._bootstrap>", line 655, in _load_unlocked
  File "<frozen importlib._bootstrap_external>", line 678, in exec_module
  File "<frozen importlib._bootstrap>", line 205, in _call_with_frames_removed
  File "/home/django_web/pyproject/mysite/polls/models.py", line 13, in <module>
    class Choice(models.Model):
  File "/home/django_web/pyproject/mysite/polls/models.py", line 22, in Choice
    question = models.ForeignKey(Question,on_delete=models.CASCADE())
TypeError: CASCADE() missing 4 required positional arguments: 'collector', 'field', 'sub_objs', and 'using'
Performing system checks...

System check identified no issues (0 silenced).
August 05, 2018 - 11:04:20
Django version 1.11.6, using settings 'mysite.settings'
Starting development server at http://127.0.0.1:8000/
Quit the server with CONTROL-C.
Unhandled exception in thread started by <function check_errors.<locals>.wrapper at 0x7fef626f0d90>
Traceback (most recent call last):
  File "/usr/local/lib/python3.6/site-packages/django/utils/autoreload.py", line 228, in wrapper
    fn(*args, **kwargs)
  File "/usr/local/lib/python3.6/site-packages/django/core/management/commands/runserver.py", line 125, in inner_run
    self.check(display_num_errors=True)
  File "/usr/local/lib/python3.6/site-packages/django/core/management/base.py", line 359, in check
    include_deployment_checks=include_deployment_checks,
  File "/usr/local/lib/python3.6/site-packages/django/core/management/base.py", line 346, in _run_checks
    return checks.run_checks(**kwargs)
  File "/usr/local/lib/python3.6/site-packages/django/core/checks/registry.py", line 81, in run_checks
    new_errors = check(app_configs=app_configs)
  File "/usr/local/lib/python3.6/site-packages/django/core/checks/urls.py", line 16, in check_url_config
    return check_resolver(resolver)
  File "/usr/local/lib/python3.6/site-packages/django/core/checks/urls.py", line 26, in check_resolver
    return check_method()
  File "/usr/local/lib/python3.6/site-packages/django/urls/resolvers.py", line 254, in check
    for pattern in self.url_patterns:
  File "/usr/local/lib/python3.6/site-packages/django/utils/functional.py", line 35, in __get__
    res = instance.__dict__[self.name] = self.func(instance)
  File "/usr/local/lib/python3.6/site-packages/django/urls/resolvers.py", line 405, in url_patterns
    patterns = getattr(self.urlconf_module, "urlpatterns", self.urlconf_module)
  File "/usr/local/lib/python3.6/site-packages/django/utils/functional.py", line 35, in __get__
    res = instance.__dict__[self.name] = self.func(instance)
  File "/usr/local/lib/python3.6/site-packages/django/urls/resolvers.py", line 398, in urlconf_module
    return import_module(self.urlconf_name)
  File "/usr/local/lib/python3.6/importlib/__init__.py", line 126, in import_module
    return _bootstrap._gcd_import(name[level:], package, level)
  File "<frozen importlib._bootstrap>", line 978, in _gcd_import
  File "<frozen importlib._bootstrap>", line 961, in _find_and_load
  File "<frozen importlib._bootstrap>", line 950, in _find_and_load_unlocked
  File "<frozen importlib._bootstrap>", line 655, in _load_unlocked
  File "<frozen importlib._bootstrap_external>", line 678, in exec_module
  File "<frozen importlib._bootstrap>", line 205, in _call_with_frames_removed
  File "/home/django_web/pyproject/mysite/mysite/urls.py", line 21, in <module>
    url(r'^admin/', admin.site.urls),
  File "/usr/local/lib/python3.6/site-packages/django/contrib/admin/sites.py", line 280, in urls
    return self.get_urls(), 'admin', self.name
  File "/usr/local/lib/python3.6/site-packages/django/contrib/admin/sites.py", line 264, in get_urls
    url(r'^%s/%s/' % (model._meta.app_label, model._meta.model_name), include(model_admin.urls)),
AttributeError: 'Choice' object has no attribute 'urls'
Performing system checks...

